[2025-08-01T08:42:45.469+0000] {local_task_job_runner.py:123} INFO - ::group::Pre task execution logs
[2025-08-01T08:42:45.488+0000] {taskinstance.py:2613} INFO - Dependencies all met for dep_context=non-requeueable deps ti=<TaskInstance: world_population_ETL_dag_43.get_csv_file_task manual__2025-08-01T08:42:39.545930+00:00 [queued]>
[2025-08-01T08:42:45.500+0000] {taskinstance.py:2613} INFO - Dependencies all met for dep_context=requeueable deps ti=<TaskInstance: world_population_ETL_dag_43.get_csv_file_task manual__2025-08-01T08:42:39.545930+00:00 [queued]>
[2025-08-01T08:42:45.500+0000] {taskinstance.py:2866} INFO - Starting attempt 1 of 2
[2025-08-01T08:42:45.511+0000] {taskinstance.py:2889} INFO - Executing <Task(PythonOperator): get_csv_file_task> on 2025-08-01 08:42:39.545930+00:00
[2025-08-01T08:42:45.525+0000] {standard_task_runner.py:104} INFO - Running: ['***', 'tasks', 'run', 'world_population_ETL_dag_43', 'get_csv_file_task', 'manual__2025-08-01T08:42:39.545930+00:00', '--job-id', '9', '--raw', '--subdir', 'DAGS_FOLDER/project_01_dag.py', '--cfg-path', '/tmp/tmpyr5c75ym']
[2025-08-01T08:42:45.527+0000] {logging_mixin.py:190} WARNING - /home/***/.local/lib/python3.12/site-packages/***/task/task_runner/standard_task_runner.py:70 DeprecationWarning: This process (pid=792) is multi-threaded, use of fork() may lead to deadlocks in the child.
[2025-08-01T08:42:45.528+0000] {standard_task_runner.py:105} INFO - Job 9: Subtask get_csv_file_task
[2025-08-01T08:42:45.528+0000] {standard_task_runner.py:72} INFO - Started process 798 to run task
[2025-08-01T08:42:45.579+0000] {task_command.py:467} INFO - Running <TaskInstance: world_population_ETL_dag_43.get_csv_file_task manual__2025-08-01T08:42:39.545930+00:00 [running]> on host 3a7d040e403d
[2025-08-01T08:42:45.651+0000] {taskinstance.py:3132} INFO - Exporting env vars: AIRFLOW_CTX_DAG_OWNER='givi-abe' AIRFLOW_CTX_DAG_ID='world_population_ETL_dag_43' AIRFLOW_CTX_TASK_ID='get_csv_file_task' AIRFLOW_CTX_EXECUTION_DATE='2025-08-01T08:42:39.545930+00:00' AIRFLOW_CTX_TRY_NUMBER='1' AIRFLOW_CTX_DAG_RUN_ID='manual__2025-08-01T08:42:39.545930+00:00'
[2025-08-01T08:42:45.652+0000] {taskinstance.py:731} INFO - ::endgroup::
[2025-08-01T08:42:45.712+0000] {taskinstance.py:3311} ERROR - Task failed with exception
Traceback (most recent call last):
  File "/opt/airflow/dags/project_01_dag.py", line 433, in get_csv_file
    df.to_csv(local_file_location, index=False)
  File "/home/airflow/.local/lib/python3.12/site-packages/pandas/core/generic.py", line 3902, in to_csv
    return DataFrameRenderer(formatter).to_csv(
           ^^^^^^^^^^^^^^^^^^^^^^^^^^^^^^^^^^^^
  File "/home/airflow/.local/lib/python3.12/site-packages/pandas/io/formats/format.py", line 1152, in to_csv
    csv_formatter.save()
  File "/home/airflow/.local/lib/python3.12/site-packages/pandas/io/formats/csvs.py", line 247, in save
    with get_handle(
         ^^^^^^^^^^^
  File "/home/airflow/.local/lib/python3.12/site-packages/pandas/io/common.py", line 863, in get_handle
    handle = open(
             ^^^^^
PermissionError: [Errno 13] Permission denied: './data/world_population_2025-08-01.csv'

The above exception was the direct cause of the following exception:

Traceback (most recent call last):
  File "/home/airflow/.local/lib/python3.12/site-packages/airflow/models/taskinstance.py", line 767, in _execute_task
    result = _execute_callable(context=context, **execute_callable_kwargs)
             ^^^^^^^^^^^^^^^^^^^^^^^^^^^^^^^^^^^^^^^^^^^^^^^^^^^^^^^^^^^^^
  File "/home/airflow/.local/lib/python3.12/site-packages/airflow/models/taskinstance.py", line 733, in _execute_callable
    return ExecutionCallableRunner(
           ^^^^^^^^^^^^^^^^^^^^^^^^
  File "/home/airflow/.local/lib/python3.12/site-packages/airflow/utils/operator_helpers.py", line 252, in run
    return self.func(*args, **kwargs)
           ^^^^^^^^^^^^^^^^^^^^^^^^^^
  File "/home/airflow/.local/lib/python3.12/site-packages/airflow/models/baseoperator.py", line 422, in wrapper
    return func(self, *args, **kwargs)
           ^^^^^^^^^^^^^^^^^^^^^^^^^^^
  File "/home/airflow/.local/lib/python3.12/site-packages/airflow/operators/python.py", line 238, in execute
    return_value = self.execute_callable()
                   ^^^^^^^^^^^^^^^^^^^^^^^
  File "/home/airflow/.local/lib/python3.12/site-packages/airflow/operators/python.py", line 256, in execute_callable
    return runner.run(*self.op_args, **self.op_kwargs)
           ^^^^^^^^^^^^^^^^^^^^^^^^^^^^^^^^^^^^^^^^^^^
  File "/home/airflow/.local/lib/python3.12/site-packages/airflow/utils/operator_helpers.py", line 252, in run
    return self.func(*args, **kwargs)
           ^^^^^^^^^^^^^^^^^^^^^^^^^^
  File "/opt/airflow/dags/project_01_dag.py", line 436, in get_csv_file
    raise Exception("Error loading data to csv file:", e) from e
Exception: ('Error loading data to csv file:', PermissionError(13, 'Permission denied'))
[2025-08-01T08:42:45.725+0000] {taskinstance.py:1225} INFO - Marking task as UP_FOR_RETRY. dag_id=world_population_ETL_dag_43, task_id=get_csv_file_task, run_id=manual__2025-08-01T08:42:39.545930+00:00, execution_date=20250801T084239, start_date=20250801T084245, end_date=20250801T084245
[2025-08-01T08:42:45.734+0000] {taskinstance.py:340} INFO - ::group::Post task execution logs
[2025-08-01T08:42:45.735+0000] {standard_task_runner.py:124} ERROR - Failed to execute job 9 for task get_csv_file_task (('Error loading data to csv file:', PermissionError(13, 'Permission denied')); 798)
Traceback (most recent call last):
  File "/opt/airflow/dags/project_01_dag.py", line 433, in get_csv_file
    df.to_csv(local_file_location, index=False)
  File "/home/airflow/.local/lib/python3.12/site-packages/pandas/core/generic.py", line 3902, in to_csv
    return DataFrameRenderer(formatter).to_csv(
           ^^^^^^^^^^^^^^^^^^^^^^^^^^^^^^^^^^^^
  File "/home/airflow/.local/lib/python3.12/site-packages/pandas/io/formats/format.py", line 1152, in to_csv
    csv_formatter.save()
  File "/home/airflow/.local/lib/python3.12/site-packages/pandas/io/formats/csvs.py", line 247, in save
    with get_handle(
         ^^^^^^^^^^^
  File "/home/airflow/.local/lib/python3.12/site-packages/pandas/io/common.py", line 863, in get_handle
    handle = open(
             ^^^^^
PermissionError: [Errno 13] Permission denied: './data/world_population_2025-08-01.csv'

The above exception was the direct cause of the following exception:

Traceback (most recent call last):
  File "/home/airflow/.local/lib/python3.12/site-packages/airflow/task/task_runner/standard_task_runner.py", line 117, in _start_by_fork
    ret = args.func(args, dag=self.dag)
          ^^^^^^^^^^^^^^^^^^^^^^^^^^^^^
  File "/home/airflow/.local/lib/python3.12/site-packages/airflow/cli/cli_config.py", line 49, in command
    return func(*args, **kwargs)
           ^^^^^^^^^^^^^^^^^^^^^
  File "/home/airflow/.local/lib/python3.12/site-packages/airflow/utils/cli.py", line 116, in wrapper
    return f(*args, **kwargs)
           ^^^^^^^^^^^^^^^^^^
  File "/home/airflow/.local/lib/python3.12/site-packages/airflow/cli/commands/task_command.py", line 483, in task_run
    task_return_code = _run_task_by_selected_method(args, _dag, ti)
                       ^^^^^^^^^^^^^^^^^^^^^^^^^^^^^^^^^^^^^^^^^^^^
  File "/home/airflow/.local/lib/python3.12/site-packages/airflow/cli/commands/task_command.py", line 256, in _run_task_by_selected_method
    return _run_raw_task(args, ti)
           ^^^^^^^^^^^^^^^^^^^^^^^
  File "/home/airflow/.local/lib/python3.12/site-packages/airflow/cli/commands/task_command.py", line 341, in _run_raw_task
    return ti._run_raw_task(
           ^^^^^^^^^^^^^^^^^
  File "/home/airflow/.local/lib/python3.12/site-packages/airflow/utils/session.py", line 97, in wrapper
    return func(*args, session=session, **kwargs)
           ^^^^^^^^^^^^^^^^^^^^^^^^^^^^^^^^^^^^^^
  File "/home/airflow/.local/lib/python3.12/site-packages/airflow/models/taskinstance.py", line 3005, in _run_raw_task
    return _run_raw_task(
           ^^^^^^^^^^^^^^
  File "/home/airflow/.local/lib/python3.12/site-packages/airflow/models/taskinstance.py", line 273, in _run_raw_task
    TaskInstance._execute_task_with_callbacks(
  File "/home/airflow/.local/lib/python3.12/site-packages/airflow/models/taskinstance.py", line 3159, in _execute_task_with_callbacks
    result = self._execute_task(context, task_orig)
             ^^^^^^^^^^^^^^^^^^^^^^^^^^^^^^^^^^^^^^
  File "/home/airflow/.local/lib/python3.12/site-packages/airflow/models/taskinstance.py", line 3183, in _execute_task
    return _execute_task(self, context, task_orig)
           ^^^^^^^^^^^^^^^^^^^^^^^^^^^^^^^^^^^^^^^
  File "/home/airflow/.local/lib/python3.12/site-packages/airflow/models/taskinstance.py", line 767, in _execute_task
    result = _execute_callable(context=context, **execute_callable_kwargs)
             ^^^^^^^^^^^^^^^^^^^^^^^^^^^^^^^^^^^^^^^^^^^^^^^^^^^^^^^^^^^^^
  File "/home/airflow/.local/lib/python3.12/site-packages/airflow/models/taskinstance.py", line 733, in _execute_callable
    return ExecutionCallableRunner(
           ^^^^^^^^^^^^^^^^^^^^^^^^
  File "/home/airflow/.local/lib/python3.12/site-packages/airflow/utils/operator_helpers.py", line 252, in run
    return self.func(*args, **kwargs)
           ^^^^^^^^^^^^^^^^^^^^^^^^^^
  File "/home/airflow/.local/lib/python3.12/site-packages/airflow/models/baseoperator.py", line 422, in wrapper
    return func(self, *args, **kwargs)
           ^^^^^^^^^^^^^^^^^^^^^^^^^^^
  File "/home/airflow/.local/lib/python3.12/site-packages/airflow/operators/python.py", line 238, in execute
    return_value = self.execute_callable()
                   ^^^^^^^^^^^^^^^^^^^^^^^
  File "/home/airflow/.local/lib/python3.12/site-packages/airflow/operators/python.py", line 256, in execute_callable
    return runner.run(*self.op_args, **self.op_kwargs)
           ^^^^^^^^^^^^^^^^^^^^^^^^^^^^^^^^^^^^^^^^^^^
  File "/home/airflow/.local/lib/python3.12/site-packages/airflow/utils/operator_helpers.py", line 252, in run
    return self.func(*args, **kwargs)
           ^^^^^^^^^^^^^^^^^^^^^^^^^^
  File "/opt/airflow/dags/project_01_dag.py", line 436, in get_csv_file
    raise Exception("Error loading data to csv file:", e) from e
Exception: ('Error loading data to csv file:', PermissionError(13, 'Permission denied'))
[2025-08-01T08:42:45.783+0000] {local_task_job_runner.py:266} INFO - Task exited with return code 1
[2025-08-01T08:42:45.802+0000] {taskinstance.py:3895} INFO - 0 downstream tasks scheduled from follow-on schedule check
[2025-08-01T08:42:45.803+0000] {local_task_job_runner.py:245} INFO - ::endgroup::
