[2025-07-31T12:10:03.796+0000] {local_task_job_runner.py:123} INFO - ::group::Pre task execution logs
[2025-07-31T12:10:03.808+0000] {taskinstance.py:2613} INFO - Dependencies all met for dep_context=non-requeueable deps ti=<TaskInstance: world_population_ETL_dag_43.consume_and_insert_task manual__2025-07-31T12:09:54.468839+00:00 [queued]>
[2025-07-31T12:10:03.813+0000] {taskinstance.py:2613} INFO - Dependencies all met for dep_context=requeueable deps ti=<TaskInstance: world_population_ETL_dag_43.consume_and_insert_task manual__2025-07-31T12:09:54.468839+00:00 [queued]>
[2025-07-31T12:10:03.813+0000] {taskinstance.py:2866} INFO - Starting attempt 1 of 2
[2025-07-31T12:10:03.820+0000] {taskinstance.py:2889} INFO - Executing <Task(PythonOperator): consume_and_insert_task> on 2025-07-31 12:09:54.468839+00:00
[2025-07-31T12:10:03.829+0000] {standard_task_runner.py:104} INFO - Running: ['***', 'tasks', 'run', 'world_population_ETL_dag_43', 'consume_and_insert_task', 'manual__2025-07-31T12:09:54.468839+00:00', '--job-id', '6', '--raw', '--subdir', 'DAGS_FOLDER/project_01_dag.py', '--cfg-path', '/tmp/tmpruu1oxut']
[2025-07-31T12:10:03.831+0000] {standard_task_runner.py:105} INFO - Job 6: Subtask consume_and_insert_task
[2025-07-31T12:10:03.831+0000] {logging_mixin.py:190} WARNING - /home/***/.local/lib/python3.12/site-packages/***/task/task_runner/standard_task_runner.py:70 DeprecationWarning: This process (pid=223) is multi-threaded, use of fork() may lead to deadlocks in the child.
[2025-07-31T12:10:03.832+0000] {standard_task_runner.py:72} INFO - Started process 225 to run task
[2025-07-31T12:10:03.859+0000] {task_command.py:467} INFO - Running <TaskInstance: world_population_ETL_dag_43.consume_and_insert_task manual__2025-07-31T12:09:54.468839+00:00 [running]> on host 1e069286f646
[2025-07-31T12:10:03.907+0000] {taskinstance.py:3132} INFO - Exporting env vars: AIRFLOW_CTX_DAG_OWNER='givi-abe' AIRFLOW_CTX_DAG_ID='world_population_ETL_dag_43' AIRFLOW_CTX_TASK_ID='consume_and_insert_task' AIRFLOW_CTX_EXECUTION_DATE='2025-07-31T12:09:54.468839+00:00' AIRFLOW_CTX_TRY_NUMBER='1' AIRFLOW_CTX_DAG_RUN_ID='manual__2025-07-31T12:09:54.468839+00:00'
[2025-07-31T12:10:03.908+0000] {taskinstance.py:731} INFO - ::endgroup::
[2025-07-31T12:10:03.918+0000] {conn.py:396} INFO - <BrokerConnection client_id=kafka-python-2.2.15, node_id=bootstrap-0 host=kafka:9092 <connecting> [IPv4 ('172.18.0.7', 9092)]>: connecting to kafka:9092 [('172.18.0.7', 9092) IPv4]
[2025-07-31T12:10:03.920+0000] {conn.py:618} INFO - <BrokerConnection client_id=kafka-python-2.2.15, node_id=bootstrap-0 host=kafka:9092 <checking_api_versions_recv> [IPv4 ('172.18.0.7', 9092)]>: Broker version identified as 2.6
[2025-07-31T12:10:03.920+0000] {conn.py:457} INFO - <BrokerConnection client_id=kafka-python-2.2.15, node_id=bootstrap-0 host=kafka:9092 <connected> [IPv4 ('172.18.0.7', 9092)]>: Connection complete.
[2025-07-31T12:10:03.921+0000] {subscription_state.py:181} INFO - Updating subscribed topics to: ('ETL-PROJECT',)
[2025-07-31T12:10:03.924+0000] {logging_mixin.py:190} INFO - ðŸš¨ Error: connection to server at "postgres" (172.18.0.6), port 5432 failed: FATAL:  password authentication failed for user "root"
[2025-07-31T12:10:03.924+0000] {taskinstance.py:3311} ERROR - Task failed with exception
Traceback (most recent call last):
  File "/opt/airflow/dags/project_01_dag.py", line 297, in consume_and_insert
    conn = psycopg2.connect(
           ^^^^^^^^^^^^^^^^^
  File "/home/airflow/.local/lib/python3.12/site-packages/psycopg2/__init__.py", line 122, in connect
    conn = _connect(dsn, connection_factory=connection_factory, **kwasync)
           ^^^^^^^^^^^^^^^^^^^^^^^^^^^^^^^^^^^^^^^^^^^^^^^^^^^^^^^^^^^^^^^
psycopg2.OperationalError: connection to server at "postgres" (172.18.0.6), port 5432 failed: FATAL:  password authentication failed for user "root"


During handling of the above exception, another exception occurred:

Traceback (most recent call last):
  File "/opt/airflow/dags/project_01_dag.py", line 352, in consume_and_insert
    conn.rollback()
    ^^^^
UnboundLocalError: cannot access local variable 'conn' where it is not associated with a value

During handling of the above exception, another exception occurred:

Traceback (most recent call last):
  File "/home/airflow/.local/lib/python3.12/site-packages/airflow/models/taskinstance.py", line 767, in _execute_task
    result = _execute_callable(context=context, **execute_callable_kwargs)
             ^^^^^^^^^^^^^^^^^^^^^^^^^^^^^^^^^^^^^^^^^^^^^^^^^^^^^^^^^^^^^
  File "/home/airflow/.local/lib/python3.12/site-packages/airflow/models/taskinstance.py", line 733, in _execute_callable
    return ExecutionCallableRunner(
           ^^^^^^^^^^^^^^^^^^^^^^^^
  File "/home/airflow/.local/lib/python3.12/site-packages/airflow/utils/operator_helpers.py", line 252, in run
    return self.func(*args, **kwargs)
           ^^^^^^^^^^^^^^^^^^^^^^^^^^
  File "/home/airflow/.local/lib/python3.12/site-packages/airflow/models/baseoperator.py", line 422, in wrapper
    return func(self, *args, **kwargs)
           ^^^^^^^^^^^^^^^^^^^^^^^^^^^
  File "/home/airflow/.local/lib/python3.12/site-packages/airflow/operators/python.py", line 238, in execute
    return_value = self.execute_callable()
                   ^^^^^^^^^^^^^^^^^^^^^^^
  File "/home/airflow/.local/lib/python3.12/site-packages/airflow/operators/python.py", line 256, in execute_callable
    return runner.run(*self.op_args, **self.op_kwargs)
           ^^^^^^^^^^^^^^^^^^^^^^^^^^^^^^^^^^^^^^^^^^^
  File "/home/airflow/.local/lib/python3.12/site-packages/airflow/utils/operator_helpers.py", line 252, in run
    return self.func(*args, **kwargs)
           ^^^^^^^^^^^^^^^^^^^^^^^^^^
  File "/opt/airflow/dags/project_01_dag.py", line 354, in consume_and_insert
    cursor.close()
    ^^^^^^
UnboundLocalError: cannot access local variable 'cursor' where it is not associated with a value
[2025-07-31T12:10:03.934+0000] {taskinstance.py:1225} INFO - Marking task as UP_FOR_RETRY. dag_id=world_population_ETL_dag_43, task_id=consume_and_insert_task, run_id=manual__2025-07-31T12:09:54.468839+00:00, execution_date=20250731T120954, start_date=20250731T121003, end_date=20250731T121003
[2025-07-31T12:10:03.944+0000] {taskinstance.py:340} INFO - ::group::Post task execution logs
[2025-07-31T12:10:03.945+0000] {standard_task_runner.py:124} ERROR - Failed to execute job 6 for task consume_and_insert_task (cannot access local variable 'cursor' where it is not associated with a value; 225)
Traceback (most recent call last):
  File "/opt/airflow/dags/project_01_dag.py", line 297, in consume_and_insert
    conn = psycopg2.connect(
           ^^^^^^^^^^^^^^^^^
  File "/home/airflow/.local/lib/python3.12/site-packages/psycopg2/__init__.py", line 122, in connect
    conn = _connect(dsn, connection_factory=connection_factory, **kwasync)
           ^^^^^^^^^^^^^^^^^^^^^^^^^^^^^^^^^^^^^^^^^^^^^^^^^^^^^^^^^^^^^^^
psycopg2.OperationalError: connection to server at "postgres" (172.18.0.6), port 5432 failed: FATAL:  password authentication failed for user "root"


During handling of the above exception, another exception occurred:

Traceback (most recent call last):
  File "/opt/airflow/dags/project_01_dag.py", line 352, in consume_and_insert
    conn.rollback()
    ^^^^
UnboundLocalError: cannot access local variable 'conn' where it is not associated with a value

During handling of the above exception, another exception occurred:

Traceback (most recent call last):
  File "/home/airflow/.local/lib/python3.12/site-packages/airflow/task/task_runner/standard_task_runner.py", line 117, in _start_by_fork
    ret = args.func(args, dag=self.dag)
          ^^^^^^^^^^^^^^^^^^^^^^^^^^^^^
  File "/home/airflow/.local/lib/python3.12/site-packages/airflow/cli/cli_config.py", line 49, in command
    return func(*args, **kwargs)
           ^^^^^^^^^^^^^^^^^^^^^
  File "/home/airflow/.local/lib/python3.12/site-packages/airflow/utils/cli.py", line 116, in wrapper
    return f(*args, **kwargs)
           ^^^^^^^^^^^^^^^^^^
  File "/home/airflow/.local/lib/python3.12/site-packages/airflow/cli/commands/task_command.py", line 483, in task_run
    task_return_code = _run_task_by_selected_method(args, _dag, ti)
                       ^^^^^^^^^^^^^^^^^^^^^^^^^^^^^^^^^^^^^^^^^^^^
  File "/home/airflow/.local/lib/python3.12/site-packages/airflow/cli/commands/task_command.py", line 256, in _run_task_by_selected_method
    return _run_raw_task(args, ti)
           ^^^^^^^^^^^^^^^^^^^^^^^
  File "/home/airflow/.local/lib/python3.12/site-packages/airflow/cli/commands/task_command.py", line 341, in _run_raw_task
    return ti._run_raw_task(
           ^^^^^^^^^^^^^^^^^
  File "/home/airflow/.local/lib/python3.12/site-packages/airflow/utils/session.py", line 97, in wrapper
    return func(*args, session=session, **kwargs)
           ^^^^^^^^^^^^^^^^^^^^^^^^^^^^^^^^^^^^^^
  File "/home/airflow/.local/lib/python3.12/site-packages/airflow/models/taskinstance.py", line 3005, in _run_raw_task
    return _run_raw_task(
           ^^^^^^^^^^^^^^
  File "/home/airflow/.local/lib/python3.12/site-packages/airflow/models/taskinstance.py", line 273, in _run_raw_task
    TaskInstance._execute_task_with_callbacks(
  File "/home/airflow/.local/lib/python3.12/site-packages/airflow/models/taskinstance.py", line 3159, in _execute_task_with_callbacks
    result = self._execute_task(context, task_orig)
             ^^^^^^^^^^^^^^^^^^^^^^^^^^^^^^^^^^^^^^
  File "/home/airflow/.local/lib/python3.12/site-packages/airflow/models/taskinstance.py", line 3183, in _execute_task
    return _execute_task(self, context, task_orig)
           ^^^^^^^^^^^^^^^^^^^^^^^^^^^^^^^^^^^^^^^
  File "/home/airflow/.local/lib/python3.12/site-packages/airflow/models/taskinstance.py", line 767, in _execute_task
    result = _execute_callable(context=context, **execute_callable_kwargs)
             ^^^^^^^^^^^^^^^^^^^^^^^^^^^^^^^^^^^^^^^^^^^^^^^^^^^^^^^^^^^^^
  File "/home/airflow/.local/lib/python3.12/site-packages/airflow/models/taskinstance.py", line 733, in _execute_callable
    return ExecutionCallableRunner(
           ^^^^^^^^^^^^^^^^^^^^^^^^
  File "/home/airflow/.local/lib/python3.12/site-packages/airflow/utils/operator_helpers.py", line 252, in run
    return self.func(*args, **kwargs)
           ^^^^^^^^^^^^^^^^^^^^^^^^^^
  File "/home/airflow/.local/lib/python3.12/site-packages/airflow/models/baseoperator.py", line 422, in wrapper
    return func(self, *args, **kwargs)
           ^^^^^^^^^^^^^^^^^^^^^^^^^^^
  File "/home/airflow/.local/lib/python3.12/site-packages/airflow/operators/python.py", line 238, in execute
    return_value = self.execute_callable()
                   ^^^^^^^^^^^^^^^^^^^^^^^
  File "/home/airflow/.local/lib/python3.12/site-packages/airflow/operators/python.py", line 256, in execute_callable
    return runner.run(*self.op_args, **self.op_kwargs)
           ^^^^^^^^^^^^^^^^^^^^^^^^^^^^^^^^^^^^^^^^^^^
  File "/home/airflow/.local/lib/python3.12/site-packages/airflow/utils/operator_helpers.py", line 252, in run
    return self.func(*args, **kwargs)
           ^^^^^^^^^^^^^^^^^^^^^^^^^^
  File "/opt/airflow/dags/project_01_dag.py", line 354, in consume_and_insert
    cursor.close()
    ^^^^^^
UnboundLocalError: cannot access local variable 'cursor' where it is not associated with a value
[2025-07-31T12:10:03.965+0000] {local_task_job_runner.py:266} INFO - Task exited with return code 1
[2025-07-31T12:10:03.982+0000] {taskinstance.py:3895} INFO - 0 downstream tasks scheduled from follow-on schedule check
[2025-07-31T12:10:03.984+0000] {local_task_job_runner.py:245} INFO - ::endgroup::
