[2025-04-14T15:06:59.303+0000] {taskinstance.py:1083} INFO - Dependencies all met for <TaskInstance: HemaDag.create_table manual__2025-04-14T15:06:57.738403+00:00 [queued]>
[2025-04-14T15:06:59.316+0000] {taskinstance.py:1083} INFO - Dependencies all met for <TaskInstance: HemaDag.create_table manual__2025-04-14T15:06:57.738403+00:00 [queued]>
[2025-04-14T15:06:59.316+0000] {taskinstance.py:1279} INFO - 
--------------------------------------------------------------------------------
[2025-04-14T15:06:59.316+0000] {taskinstance.py:1280} INFO - Starting attempt 1 of 1
[2025-04-14T15:06:59.316+0000] {taskinstance.py:1281} INFO - 
--------------------------------------------------------------------------------
[2025-04-14T15:06:59.342+0000] {taskinstance.py:1300} INFO - Executing <Task(BashOperator): create_table> on 2025-04-14 15:06:57.738403+00:00
[2025-04-14T15:06:59.354+0000] {standard_task_runner.py:55} INFO - Started process 390 to run task
[2025-04-14T15:06:59.359+0000] {standard_task_runner.py:82} INFO - Running: ['***', 'tasks', 'run', 'HemaDag', 'create_table', 'manual__2025-04-14T15:06:57.738403+00:00', '--job-id', '9', '--raw', '--subdir', 'DAGS_FOLDER/day.py', '--cfg-path', '/tmp/tmp_ia15ko1']
[2025-04-14T15:06:59.361+0000] {standard_task_runner.py:83} INFO - Job 9: Subtask create_table
[2025-04-14T15:06:59.452+0000] {task_command.py:388} INFO - Running <TaskInstance: HemaDag.create_table manual__2025-04-14T15:06:57.738403+00:00 [running]> on host 0c4d66587ca1
[2025-04-14T15:06:59.555+0000] {taskinstance.py:1509} INFO - Exporting the following env vars:
AIRFLOW_CTX_DAG_OWNER=***
AIRFLOW_CTX_DAG_ID=HemaDag
AIRFLOW_CTX_TASK_ID=create_table
AIRFLOW_CTX_EXECUTION_DATE=2025-04-14T15:06:57.738403+00:00
AIRFLOW_CTX_TRY_NUMBER=1
AIRFLOW_CTX_DAG_RUN_ID=manual__2025-04-14T15:06:57.738403+00:00
[2025-04-14T15:06:59.557+0000] {subprocess.py:63} INFO - Tmp dir root location: 
 /tmp
[2025-04-14T15:06:59.557+0000] {subprocess.py:75} INFO - Running command: ['/bin/bash', '-c', 'python3 /opt/***/scripts/create_table.py']
[2025-04-14T15:06:59.578+0000] {subprocess.py:86} INFO - Output:
[2025-04-14T15:07:00.306+0000] {subprocess.py:93} INFO - ‚ùå Error creating table: connection to server at "localhost" (::1), port 5432 failed: Connection refused
[2025-04-14T15:07:00.306+0000] {subprocess.py:93} INFO - 	Is the server running on that host and accepting TCP/IP connections?
[2025-04-14T15:07:00.307+0000] {subprocess.py:93} INFO - connection to server at "localhost" (127.0.0.1), port 5432 failed: Connection refused
[2025-04-14T15:07:00.307+0000] {subprocess.py:93} INFO - 	Is the server running on that host and accepting TCP/IP connections?
[2025-04-14T15:07:00.307+0000] {subprocess.py:93} INFO - 
[2025-04-14T15:07:00.307+0000] {subprocess.py:93} INFO - Traceback (most recent call last):
[2025-04-14T15:07:00.307+0000] {subprocess.py:93} INFO -   File "/opt/***/scripts/create_table.py", line 49, in <module>
[2025-04-14T15:07:00.307+0000] {subprocess.py:93} INFO -     create_table()
[2025-04-14T15:07:00.308+0000] {subprocess.py:93} INFO -   File "/opt/***/scripts/create_table.py", line 46, in create_table
[2025-04-14T15:07:00.308+0000] {subprocess.py:93} INFO -     cursor.close()
[2025-04-14T15:07:00.308+0000] {subprocess.py:93} INFO - UnboundLocalError: local variable 'cursor' referenced before assignment
[2025-04-14T15:07:00.351+0000] {subprocess.py:97} INFO - Command exited with return code 1
[2025-04-14T15:07:00.372+0000] {taskinstance.py:1768} ERROR - Task failed with exception
Traceback (most recent call last):
  File "/home/airflow/.local/lib/python3.7/site-packages/airflow/operators/bash.py", line 197, in execute
    f"Bash command failed. The command returned a non-zero exit code {result.exit_code}."
airflow.exceptions.AirflowException: Bash command failed. The command returned a non-zero exit code 1.
[2025-04-14T15:07:00.378+0000] {taskinstance.py:1323} INFO - Marking task as FAILED. dag_id=HemaDag, task_id=create_table, execution_date=20250414T150657, start_date=20250414T150659, end_date=20250414T150700
[2025-04-14T15:07:00.404+0000] {standard_task_runner.py:105} ERROR - Failed to execute job 9 for task create_table (Bash command failed. The command returned a non-zero exit code 1.; 390)
[2025-04-14T15:07:00.453+0000] {local_task_job.py:208} INFO - Task exited with return code 1
[2025-04-14T15:07:00.478+0000] {taskinstance.py:2578} INFO - 0 downstream tasks scheduled from follow-on schedule check
