[2025-07-31T13:41:06.121+0000] {local_task_job_runner.py:123} INFO - ::group::Pre task execution logs
[2025-07-31T13:41:06.132+0000] {taskinstance.py:2613} INFO - Dependencies all met for dep_context=non-requeueable deps ti=<TaskInstance: world_population_ETL_dag_43.send_dataframe_to_kafka_task manual__2025-07-31T13:41:00.804261+00:00 [queued]>
[2025-07-31T13:41:06.137+0000] {taskinstance.py:2613} INFO - Dependencies all met for dep_context=requeueable deps ti=<TaskInstance: world_population_ETL_dag_43.send_dataframe_to_kafka_task manual__2025-07-31T13:41:00.804261+00:00 [queued]>
[2025-07-31T13:41:06.137+0000] {taskinstance.py:2866} INFO - Starting attempt 1 of 2
[2025-07-31T13:41:06.145+0000] {taskinstance.py:2889} INFO - Executing <Task(PythonOperator): send_dataframe_to_kafka_task> on 2025-07-31 13:41:00.804261+00:00
[2025-07-31T13:41:06.155+0000] {logging_mixin.py:190} WARNING - /home/***/.local/lib/python3.12/site-packages/***/task/task_runner/standard_task_runner.py:70 DeprecationWarning: This process (pid=921) is multi-threaded, use of fork() may lead to deadlocks in the child.
[2025-07-31T13:41:06.155+0000] {standard_task_runner.py:72} INFO - Started process 924 to run task
[2025-07-31T13:41:06.155+0000] {standard_task_runner.py:104} INFO - Running: ['***', 'tasks', 'run', 'world_population_ETL_dag_43', 'send_dataframe_to_kafka_task', 'manual__2025-07-31T13:41:00.804261+00:00', '--job-id', '42', '--raw', '--subdir', 'DAGS_FOLDER/project_01_dag.py', '--cfg-path', '/tmp/tmpqb8cns87']
[2025-07-31T13:41:06.156+0000] {standard_task_runner.py:105} INFO - Job 42: Subtask send_dataframe_to_kafka_task
[2025-07-31T13:41:06.187+0000] {task_command.py:467} INFO - Running <TaskInstance: world_population_ETL_dag_43.send_dataframe_to_kafka_task manual__2025-07-31T13:41:00.804261+00:00 [running]> on host 5caea9b1d396
[2025-07-31T13:41:06.254+0000] {taskinstance.py:3132} INFO - Exporting env vars: AIRFLOW_CTX_DAG_OWNER='givi-abe' AIRFLOW_CTX_DAG_ID='world_population_ETL_dag_43' AIRFLOW_CTX_TASK_ID='send_dataframe_to_kafka_task' AIRFLOW_CTX_EXECUTION_DATE='2025-07-31T13:41:00.804261+00:00' AIRFLOW_CTX_TRY_NUMBER='1' AIRFLOW_CTX_DAG_RUN_ID='manual__2025-07-31T13:41:00.804261+00:00'
[2025-07-31T13:41:06.255+0000] {taskinstance.py:731} INFO - ::endgroup::
[2025-07-31T13:41:06.268+0000] {conn.py:396} INFO - <BrokerConnection client_id=kafka-python-producer-1, node_id=bootstrap-0 host=kafka:9092 <connecting> [IPv4 ('172.18.0.7', 9092)]>: connecting to kafka:9092 [('172.18.0.7', 9092) IPv4]
[2025-07-31T13:41:06.270+0000] {conn.py:618} INFO - <BrokerConnection client_id=kafka-python-producer-1, node_id=bootstrap-0 host=kafka:9092 <checking_api_versions_recv> [IPv4 ('172.18.0.7', 9092)]>: Broker version identified as 2.6
[2025-07-31T13:41:06.270+0000] {conn.py:457} INFO - <BrokerConnection client_id=kafka-python-producer-1, node_id=bootstrap-0 host=kafka:9092 <connected> [IPv4 ('172.18.0.7', 9092)]>: Connection complete.
[2025-07-31T13:41:06.374+0000] {conn.py:396} INFO - <BrokerConnection client_id=kafka-python-producer-1, node_id=1 host=kafka:9092 <connecting> [IPv4 ('172.18.0.7', 9092)]>: connecting to kafka:9092 [('172.18.0.7', 9092) IPv4]
[2025-07-31T13:41:06.375+0000] {conn.py:457} INFO - <BrokerConnection client_id=kafka-python-producer-1, node_id=1 host=kafka:9092 <connected> [IPv4 ('172.18.0.7', 9092)]>: Connection complete.
[2025-07-31T13:41:06.375+0000] {conn.py:945} INFO - <BrokerConnection client_id=kafka-python-producer-1, node_id=bootstrap-0 host=kafka:9092 <connected> [IPv4 ('172.18.0.7', 9092)]>: Closing connection. 
[2025-07-31T13:41:06.478+0000] {logging_mixin.py:190} INFO - ðŸš¨ Producer error: 'country'
[2025-07-31T13:41:06.479+0000] {kafka.py:629} INFO - <KafkaProducer client_id=kafka-python-producer-1 transactional_id=None>: Closing the Kafka producer with 9223372036.0 secs timeout.
[2025-07-31T13:41:06.479+0000] {conn.py:945} INFO - <BrokerConnection client_id=kafka-python-producer-1, node_id=1 host=kafka:9092 <connected> [IPv4 ('172.18.0.7', 9092)]>: Closing connection. 
[2025-07-31T13:41:06.480+0000] {taskinstance.py:3311} ERROR - Task failed with exception
Traceback (most recent call last):
  File "/opt/airflow/dags/project_01_dag.py", line 248, in send_dataframe_to_kafka
    print(f"ðŸ“¤ Sent record: {record['country']}")
                             ~~~~~~^^^^^^^^^^^
KeyError: 'country'

During handling of the above exception, another exception occurred:

Traceback (most recent call last):
  File "/home/airflow/.local/lib/python3.12/site-packages/airflow/models/taskinstance.py", line 767, in _execute_task
    result = _execute_callable(context=context, **execute_callable_kwargs)
             ^^^^^^^^^^^^^^^^^^^^^^^^^^^^^^^^^^^^^^^^^^^^^^^^^^^^^^^^^^^^^
  File "/home/airflow/.local/lib/python3.12/site-packages/airflow/models/taskinstance.py", line 733, in _execute_callable
    return ExecutionCallableRunner(
           ^^^^^^^^^^^^^^^^^^^^^^^^
  File "/home/airflow/.local/lib/python3.12/site-packages/airflow/utils/operator_helpers.py", line 252, in run
    return self.func(*args, **kwargs)
           ^^^^^^^^^^^^^^^^^^^^^^^^^^
  File "/home/airflow/.local/lib/python3.12/site-packages/airflow/models/baseoperator.py", line 422, in wrapper
    return func(self, *args, **kwargs)
           ^^^^^^^^^^^^^^^^^^^^^^^^^^^
  File "/home/airflow/.local/lib/python3.12/site-packages/airflow/operators/python.py", line 238, in execute
    return_value = self.execute_callable()
                   ^^^^^^^^^^^^^^^^^^^^^^^
  File "/home/airflow/.local/lib/python3.12/site-packages/airflow/operators/python.py", line 256, in execute_callable
    return runner.run(*self.op_args, **self.op_kwargs)
           ^^^^^^^^^^^^^^^^^^^^^^^^^^^^^^^^^^^^^^^^^^^
  File "/home/airflow/.local/lib/python3.12/site-packages/airflow/utils/operator_helpers.py", line 252, in run
    return self.func(*args, **kwargs)
           ^^^^^^^^^^^^^^^^^^^^^^^^^^
  File "/opt/airflow/dags/project_01_dag.py", line 250, in send_dataframe_to_kafka
    print(f"ðŸš¨ Failed to send record {record['country']}: {str(e)}")
                                      ~~~~~~^^^^^^^^^^^
KeyError: 'country'
[2025-07-31T13:41:06.492+0000] {taskinstance.py:1225} INFO - Marking task as UP_FOR_RETRY. dag_id=world_population_ETL_dag_43, task_id=send_dataframe_to_kafka_task, run_id=manual__2025-07-31T13:41:00.804261+00:00, execution_date=20250731T134100, start_date=20250731T134106, end_date=20250731T134106
[2025-07-31T13:41:06.505+0000] {taskinstance.py:340} INFO - ::group::Post task execution logs
[2025-07-31T13:41:06.505+0000] {standard_task_runner.py:124} ERROR - Failed to execute job 42 for task send_dataframe_to_kafka_task ('country'; 924)
Traceback (most recent call last):
  File "/opt/airflow/dags/project_01_dag.py", line 248, in send_dataframe_to_kafka
    print(f"ðŸ“¤ Sent record: {record['country']}")
                             ~~~~~~^^^^^^^^^^^
KeyError: 'country'

During handling of the above exception, another exception occurred:

Traceback (most recent call last):
  File "/home/airflow/.local/lib/python3.12/site-packages/airflow/task/task_runner/standard_task_runner.py", line 117, in _start_by_fork
    ret = args.func(args, dag=self.dag)
          ^^^^^^^^^^^^^^^^^^^^^^^^^^^^^
  File "/home/airflow/.local/lib/python3.12/site-packages/airflow/cli/cli_config.py", line 49, in command
    return func(*args, **kwargs)
           ^^^^^^^^^^^^^^^^^^^^^
  File "/home/airflow/.local/lib/python3.12/site-packages/airflow/utils/cli.py", line 116, in wrapper
    return f(*args, **kwargs)
           ^^^^^^^^^^^^^^^^^^
  File "/home/airflow/.local/lib/python3.12/site-packages/airflow/cli/commands/task_command.py", line 483, in task_run
    task_return_code = _run_task_by_selected_method(args, _dag, ti)
                       ^^^^^^^^^^^^^^^^^^^^^^^^^^^^^^^^^^^^^^^^^^^^
  File "/home/airflow/.local/lib/python3.12/site-packages/airflow/cli/commands/task_command.py", line 256, in _run_task_by_selected_method
    return _run_raw_task(args, ti)
           ^^^^^^^^^^^^^^^^^^^^^^^
  File "/home/airflow/.local/lib/python3.12/site-packages/airflow/cli/commands/task_command.py", line 341, in _run_raw_task
    return ti._run_raw_task(
           ^^^^^^^^^^^^^^^^^
  File "/home/airflow/.local/lib/python3.12/site-packages/airflow/utils/session.py", line 97, in wrapper
    return func(*args, session=session, **kwargs)
           ^^^^^^^^^^^^^^^^^^^^^^^^^^^^^^^^^^^^^^
  File "/home/airflow/.local/lib/python3.12/site-packages/airflow/models/taskinstance.py", line 3005, in _run_raw_task
    return _run_raw_task(
           ^^^^^^^^^^^^^^
  File "/home/airflow/.local/lib/python3.12/site-packages/airflow/models/taskinstance.py", line 273, in _run_raw_task
    TaskInstance._execute_task_with_callbacks(
  File "/home/airflow/.local/lib/python3.12/site-packages/airflow/models/taskinstance.py", line 3159, in _execute_task_with_callbacks
    result = self._execute_task(context, task_orig)
             ^^^^^^^^^^^^^^^^^^^^^^^^^^^^^^^^^^^^^^
  File "/home/airflow/.local/lib/python3.12/site-packages/airflow/models/taskinstance.py", line 3183, in _execute_task
    return _execute_task(self, context, task_orig)
           ^^^^^^^^^^^^^^^^^^^^^^^^^^^^^^^^^^^^^^^
  File "/home/airflow/.local/lib/python3.12/site-packages/airflow/models/taskinstance.py", line 767, in _execute_task
    result = _execute_callable(context=context, **execute_callable_kwargs)
             ^^^^^^^^^^^^^^^^^^^^^^^^^^^^^^^^^^^^^^^^^^^^^^^^^^^^^^^^^^^^^
  File "/home/airflow/.local/lib/python3.12/site-packages/airflow/models/taskinstance.py", line 733, in _execute_callable
    return ExecutionCallableRunner(
           ^^^^^^^^^^^^^^^^^^^^^^^^
  File "/home/airflow/.local/lib/python3.12/site-packages/airflow/utils/operator_helpers.py", line 252, in run
    return self.func(*args, **kwargs)
           ^^^^^^^^^^^^^^^^^^^^^^^^^^
  File "/home/airflow/.local/lib/python3.12/site-packages/airflow/models/baseoperator.py", line 422, in wrapper
    return func(self, *args, **kwargs)
           ^^^^^^^^^^^^^^^^^^^^^^^^^^^
  File "/home/airflow/.local/lib/python3.12/site-packages/airflow/operators/python.py", line 238, in execute
    return_value = self.execute_callable()
                   ^^^^^^^^^^^^^^^^^^^^^^^
  File "/home/airflow/.local/lib/python3.12/site-packages/airflow/operators/python.py", line 256, in execute_callable
    return runner.run(*self.op_args, **self.op_kwargs)
           ^^^^^^^^^^^^^^^^^^^^^^^^^^^^^^^^^^^^^^^^^^^
  File "/home/airflow/.local/lib/python3.12/site-packages/airflow/utils/operator_helpers.py", line 252, in run
    return self.func(*args, **kwargs)
           ^^^^^^^^^^^^^^^^^^^^^^^^^^
  File "/opt/airflow/dags/project_01_dag.py", line 250, in send_dataframe_to_kafka
    print(f"ðŸš¨ Failed to send record {record['country']}: {str(e)}")
                                      ~~~~~~^^^^^^^^^^^
KeyError: 'country'
[2025-07-31T13:41:06.529+0000] {local_task_job_runner.py:266} INFO - Task exited with return code 1
[2025-07-31T13:41:06.546+0000] {taskinstance.py:3895} INFO - 0 downstream tasks scheduled from follow-on schedule check
[2025-07-31T13:41:06.547+0000] {local_task_job_runner.py:245} INFO - ::endgroup::
